Ignoring exception in command restart:
Traceback (most recent call last):
  File "/home/pi/.local/lib/python3.7/site-packages/discord/ext/commands/core.py", line 85, in wrapped
    ret = await coro(*args, **kwargs)
  File "bot.py", line 174, in restart_bot
    restart = subprocess.Popen("TheMoonCowboy/restart.sh")
  File "/usr/lib/python3.7/subprocess.py", line 775, in __init__
    restore_signals, start_new_session)
  File "/usr/lib/python3.7/subprocess.py", line 1522, in _execute_child
    raise child_exception_type(errno_num, err_msg, err_filename)
FileNotFoundError: [Errno 2] No such file or directory: 'TheMoonCowboy/restart.sh': 'TheMoonCowboy/restart.sh'

The above exception was the direct cause of the following exception:

Traceback (most recent call last):
  File "/home/pi/.local/lib/python3.7/site-packages/discord/ext/commands/bot.py", line 903, in invoke
    await ctx.command.invoke(ctx)
  File "/home/pi/.local/lib/python3.7/site-packages/discord/ext/commands/core.py", line 859, in invoke
    await injected(*ctx.args, **ctx.kwargs)
  File "/home/pi/.local/lib/python3.7/site-packages/discord/ext/commands/core.py", line 94, in wrapped
    raise CommandInvokeError(exc) from exc
discord.ext.commands.errors.CommandInvokeError: Command raised an exception: FileNotFoundError: [Errno 2] No such file or directory: 'TheMoonCowboy/restart.sh': 'TheMoonCowboy/restart.sh'
Ignoring exception in command restart:
Traceback (most recent call last):
  File "/home/pi/.local/lib/python3.7/site-packages/discord/ext/commands/core.py", line 85, in wrapped
    ret = await coro(*args, **kwargs)
  File "bot.py", line 174, in restart_bot
    restart = subprocess.Popen("restart.sh")
  File "/usr/lib/python3.7/subprocess.py", line 775, in __init__
    restore_signals, start_new_session)
  File "/usr/lib/python3.7/subprocess.py", line 1522, in _execute_child
    raise child_exception_type(errno_num, err_msg, err_filename)
FileNotFoundError: [Errno 2] No such file or directory: 'restart.sh': 'restart.sh'

The above exception was the direct cause of the following exception:

Traceback (most recent call last):
  File "/home/pi/.local/lib/python3.7/site-packages/discord/ext/commands/bot.py", line 903, in invoke
    await ctx.command.invoke(ctx)
  File "/home/pi/.local/lib/python3.7/site-packages/discord/ext/commands/core.py", line 859, in invoke
    await injected(*ctx.args, **ctx.kwargs)
  File "/home/pi/.local/lib/python3.7/site-packages/discord/ext/commands/core.py", line 94, in wrapped
    raise CommandInvokeError(exc) from exc
discord.ext.commands.errors.CommandInvokeError: Command raised an exception: FileNotFoundError: [Errno 2] No such file or directory: 'restart.sh': 'restart.sh'
Ignoring exception in command restart:
Traceback (most recent call last):
  File "/home/pi/.local/lib/python3.7/site-packages/discord/ext/commands/core.py", line 85, in wrapped
    ret = await coro(*args, **kwargs)
  File "bot.py", line 175, in restart_bot
    restart = subprocess.Popen("restart.sh")
  File "/usr/lib/python3.7/subprocess.py", line 775, in __init__
    restore_signals, start_new_session)
  File "/usr/lib/python3.7/subprocess.py", line 1522, in _execute_child
    raise child_exception_type(errno_num, err_msg, err_filename)
FileNotFoundError: [Errno 2] No such file or directory: 'restart.sh': 'restart.sh'

The above exception was the direct cause of the following exception:

Traceback (most recent call last):
  File "/home/pi/.local/lib/python3.7/site-packages/discord/ext/commands/bot.py", line 903, in invoke
    await ctx.command.invoke(ctx)
  File "/home/pi/.local/lib/python3.7/site-packages/discord/ext/commands/core.py", line 859, in invoke
    await injected(*ctx.args, **ctx.kwargs)
  File "/home/pi/.local/lib/python3.7/site-packages/discord/ext/commands/core.py", line 94, in wrapped
    raise CommandInvokeError(exc) from exc
discord.ext.commands.errors.CommandInvokeError: Command raised an exception: FileNotFoundError: [Errno 2] No such file or directory: 'restart.sh': 'restart.sh'
restarting
Ignoring exception in command restart:
Traceback (most recent call last):
  File "/home/pi/.local/lib/python3.7/site-packages/discord/ext/commands/core.py", line 85, in wrapped
    ret = await coro(*args, **kwargs)
  File "bot.py", line 175, in restart_bot
    restart = subprocess.Popen("restart.sh")
  File "/usr/lib/python3.7/subprocess.py", line 775, in __init__
    restore_signals, start_new_session)
  File "/usr/lib/python3.7/subprocess.py", line 1522, in _execute_child
    raise child_exception_type(errno_num, err_msg, err_filename)
FileNotFoundError: [Errno 2] No such file or directory: 'restart.sh': 'restart.sh'

The above exception was the direct cause of the following exception:

Traceback (most recent call last):
  File "/home/pi/.local/lib/python3.7/site-packages/discord/ext/commands/bot.py", line 903, in invoke
    await ctx.command.invoke(ctx)
  File "/home/pi/.local/lib/python3.7/site-packages/discord/ext/commands/core.py", line 859, in invoke
    await injected(*ctx.args, **ctx.kwargs)
  File "/home/pi/.local/lib/python3.7/site-packages/discord/ext/commands/core.py", line 94, in wrapped
    raise CommandInvokeError(exc) from exc
discord.ext.commands.errors.CommandInvokeError: Command raised an exception: FileNotFoundError: [Errno 2] No such file or directory: 'restart.sh': 'restart.sh'
restarting
python: can't open file '3': [Errno 2] No such file or directory
python: can't open file '3': [Errno 2] No such file or directory
